不想调用拷贝构造就要增加引用，这样返回的匿名对象就转正了，不用调用拷贝构造的好处就是防止析构两次，但是我建议以后自定义的异常都重写拷贝构造和等号运算符



使用&之后就相当于使用自己定义的异常类去给这里的exception（父类）对象进行初始化

[csdn_link](https://blog.csdn.net/saturn254/article/details/105032664?ops_request_misc=&request_id=&biz_id=102&utm_term=const%20char*%20what()%20const%20throw&utm_medium=distribute.pc_search_result.none-task-blog-2~all~sobaiduweb~default-3-105032664.142^v14^control,157^v14^new_3&spm=1018.2226.3001.4187)

在catch语句体里面的处理逻辑只能使用这个新的exception对象来进行操作

涉及指针的，必须深拷贝，传引用

浅拷贝了

```
char *strcpy(char *dest, const char *src)
```

```cpp
void func02(){
	throw MyOutofrange("myself out of range");
}


class MyOutofrange:public exception{
public:
	// 构造函数
	MyOutofrange(const char* error)
	{
		pError = new char[strlen(error) + 1];
		strcpy(pError, error);
	}

关于总是提示
    warning: ISO C++ forbids converting a string constant to 'char*' [-Wwrite-strings]
解决：
    // 构造函数 加 const
	MyOutofrange(const char* error)    
```





## **三、标准库异常和自己的异常类案例代码：**

[csdn_link](https://blog.csdn.net/xujianjun229/article/details/121276437?ops_request_misc=%257B%2522request%255Fid%2522%253A%2522165519066416782246410538%2522%252C%2522scm%2522%253A%252220140713.130102334..%2522%257D&request_id=165519066416782246410538&biz_id=0&utm_medium=distribute.pc_search_result.none-task-blog-2~all~sobaiduend~default-2-121276437-null-null.142^v14^control,157^v14^new_3&utm_term=%E7%BC%96%E5%86%99%E8%87%AA%E5%B7%B1%E7%9A%84%E5%BC%82%E5%B8%B8%E7%B1%BB&spm=1018.2226.3001.4187)

```
#define _CRT_SECURE_NO_WARNINGS
#include <iostream>
#include<stdexcept>
using namespace std;
 
 
 
//标准库异常
class Person{
public:
	Person(){
		mAge = 0;
	}
	void setAge(int age){
		if (age < 0 || age > 100){
			throw out_of_range("年龄应该在0-100之间!");
		}
		this->mAge = age;
	}
public:
	int mAge;
};
 
void test01(){
 
	Person p;
 
	try{
		p.setAge(1000);
	}
	catch (exception& e){
		cout << e.what() << endl;
	}
}
 
 
//自定义异常类
class MyOutRangeException : public exception {
public:
	MyOutRangeException(const char* error) {
		int len = strlen(error) + 1;
		this->pError = new char[len];
		strcpy(this->pError, error);
	}
	virtual const char* what() const {
		return this->pError;
	}
	virtual ~MyOutRangeException() {
		cout << "析构函数!" << endl;
		if (pError != NULL) {
			delete[] this->pError;
		}
	}
public:
	char* pError;
};
 
void fun02()
{
	throw MyOutRangeException("我自己的out_of_range!");
}
 
void test02(){
 
	try{
		fun02();
	}
	catch (exception& e){
		cout << e.what() << endl;
	}
 
}
 
 
int main(void)
{
	//test01();
	test02();
	return 0;
}
```

